<?xml version="1.0"?>
<!--
	 SPDX-License-Identifier: GPL-3.0-only

	 Copyright (C) 2021  Haruki Shimotori. All right reserved.
-->

<sdf version="1.5">
	<model name="robotracer">
		<static>false</static>

<!-- ****************** Link ****************** -->
		<link name="chassis">
			<pose>0 0 0.0015 0 0 0</pose>
			<inertial>
				<mass>0.08</mass>
				<inertia>
					<ixx>0.00003</ixx>
					<ixy>0.0</ixy>
					<ixz>0.0</ixz>
					<iyy>0.00003</iyy>
					<iyz>0.0</iyz>
					<izz>0.00005</izz>
				</inertia>
			</inertial>

			<collision name="collision_base">
				<geometry>
					<box>
						<size>0.1 0.08 0.001</size>
					</box>
				</geometry>
			</collision>
			<visual name="visual_base">
				<geometry>
					<box>
						<size>0.1 0.08 0.001</size>
					</box>
				</geometry>
			</visual>
			
			<collision name="collision_sensor_bar">
				<pose>0.0975 0 0.0 0 0 0</pose>
				<geometry>
					<box>
						<size>0.095 0.01 0.001</size>
					</box>
				</geometry>
			</collision>
			<visual name="visual_sensor_bar">
				<pose>0.0975 0 0.0 0 0 0</pose>
				<geometry>
					<box>
						<size>0.095 0.01 0.001</size>
					</box>
				</geometry>
			</visual>
			
			<collision name="collision_sensor">
				<pose>0.150 0.0 0.0 0 0 0</pose>
				<geometry>
					<box>
						<size>0.010 0.100 0.001</size>
					</box>
				</geometry>
			</collision>
			<visual name="visual_sensor">
				<pose>0.150 0.0 0.0 0 0 0</pose>
				<geometry>
					<box>
						<size>0.010 0.100 0.001</size>
					</box>
				</geometry>
			</visual>

			<collision name="collision_support_left">
				<pose>0.154 0.045 -0.001 0 0 0</pose>
				<geometry>
					<sphere>
						<radius>0.0005</radius>
					</sphere>
				</geometry>
				<surface>
					<friction>
						<ode>
							<mu>0</mu>
							<mu2>0</mu2>
							<slip1>1.0</slip1>
							<slip2>1.0</slip2>
						</ode>
					</friction>
				</surface>
			</collision>
			<visual name="visual_support_left">
				<pose>0.154 0.045 -0.001 0 0 0</pose>
				<geometry>
					<sphere>
						<radius>0.0005</radius>
					</sphere>
				</geometry>
			</visual>
			<collision name="collision_support_right">
				<pose>0.154 -0.045 -0.001 0 0 0</pose>
				<geometry>
					<sphere>
						<radius>0.0005</radius>
					</sphere>
				</geometry>
				<surface>
					<friction>
						<ode>
							<mu>0</mu>
							<mu2>0</mu2>
							<slip1>1.0</slip1>
							<slip2>1.0</slip2>
						</ode>
					</friction>
				</surface>
			</collision>
			<visual name="visual_support_right">
				<pose>0.154 -0.045 -0.001 0 0 0</pose>
				<geometry>
					<sphere>
						<radius>0.0005</radius>
					</sphere>
				</geometry>
			</visual>
			<visual name="visual_imu">
				<pose>0 0 0.005 0 0 0</pose>
				<geometry>
					<box>
						<size>0.010 0.010 0.005</size>
					</box>
				</geometry>
			</visual>
			<sensor name="imu" type="imu">
				<pose>0 0 0.0025 0 0 0</pose>
				<imu>
					<angular_velocity>
						<z>
							<noise type="gaussian">
								<mean>0.0</mean>
								<stddev>2e-4</stddev>
								<bias_mean>0.0000075</bias_mean>
								<bias_stddev>0.0000008</bias_stddev>
							</noise>
						</z>
					</angular_velocity>
				</imu>
				<always_on>1</always_on>
				<update_rate>1000</update_rate>
			</sensor>
		</link>
		<link name="right_front_wheel">
			<pose>0.011 -0.055 0.009 1.5707 0 0</pose>

			<inertial>
				<mass>0.005</mass>
				<inertia>
					<ixx>0.0000003</ixx>
					<iyy>0.0000003</iyy>
					<izz>0.0000003</izz>
					<ixy>0</ixy>
					<ixz>0</ixz>
					<iyz>0</iyz>
				</inertia>
			</inertial>

			<collision name="collision">
				<geometry>
					<cylinder>
						<radius>0.01</radius>
						<length>0.01</length>
					</cylinder>
				</geometry>
				<surface>
					<friction>
						<ode>
							<mu>0.8</mu>
							<mu2>0.8</mu2>
							<slip1>0.5</slip1>
							<slip2>0.5</slip2>
						</ode>
					</friction>
				</surface>
			</collision>
			<visual name="visual">
				<geometry>
					<cylinder>
						<radius>0.01</radius>
						<length>0.01</length>
					</cylinder>
				</geometry>
			</visual>
		</link>
		<link name="left_front_wheel">
			<pose>0.011 0.055 0.009 1.5707 0 0</pose>

			<inertial>
				<mass>0.005</mass>
				<inertia>
					<ixx>0.0000003</ixx>
					<iyy>0.0000003</iyy>
					<izz>0.0000003</izz>
					<ixy>0</ixy>
					<ixz>0</ixz>
					<iyz>0</iyz>
				</inertia>
			</inertial>

			<collision name="collision">
				<geometry>
					<cylinder>
						<radius>0.01</radius>
						<length>0.01</length>
					</cylinder>
				</geometry>
				<surface>
					<friction>
						<ode>
							<mu>0.8</mu>
							<mu2>0.8</mu2>
							<slip1>0.5</slip1>
							<slip2>0.5</slip2>
						</ode>
					</friction>
				</surface>
			</collision>
			<visual name="visual">
				<geometry>
					<cylinder>
						<radius>0.01</radius>
						<length>0.01</length>
					</cylinder>
				</geometry>
			</visual>
		</link>
		
		<link name="right_rear_wheel">
			<pose>-0.011 -0.055 0.009 1.5707 0 0</pose>

			<inertial>
				<mass>0.005</mass>
				<inertia>
					<ixx>0.0000003</ixx>
					<iyy>0.0000003</iyy>
					<izz>0.0000003</izz>
					<ixy>0</ixy>
					<ixz>0</ixz>
					<iyz>0</iyz>
				</inertia>
			</inertial>

			<collision name="collision">
				<geometry>
					<cylinder>
						<radius>0.01</radius>
						<length>0.01</length>
					</cylinder>
				</geometry>
				<surface>
					<friction>
						<ode>
							<mu>0.8</mu>
							<mu2>0.8</mu2>
							<slip1>0.5</slip1>
							<slip2>0.5</slip2>
						</ode>
					</friction>
				</surface>
			</collision>
			<visual name="visual">
				<geometry>
					<cylinder>
						<radius>0.01</radius>
						<length>0.01</length>
					</cylinder>
				</geometry>
			</visual>
		</link>
		<link name="left_rear_wheel">
			<pose>-0.011 0.055 0.009 1.5707 0 0</pose>

			<inertial>
				<mass>0.005</mass>
				<inertia>
					<ixx>0.0000003</ixx>
					<iyy>0.0000003</iyy>
					<izz>0.0000003</izz>
					<ixy>0</ixy>
					<ixz>0</ixz>
					<iyz>0</iyz>
				</inertia>
			</inertial>

			<collision name="collision">
				<geometry>
					<cylinder>
						<radius>0.01</radius>
						<length>0.01</length>
					</cylinder>
				</geometry>
				<surface>
					<friction>
						<ode>
							<mu>0.8</mu>
							<mu2>0.8</mu2>
							<slip1>0.5</slip1>
							<slip2>0.5</slip2>
						</ode>
					</friction>
				</surface>
			</collision>
			<visual name="visual">
				<geometry>
					<cylinder>
						<radius>0.01</radius>
						<length>0.01</length>
					</cylinder>
				</geometry>
			</visual>
		</link>
		
		<link name="camera_link">
			<!--<pose>0.15 0.01 0.05 0 1.571 0</pose>-->
			<pose>0.0 0.0 0.0 0 0 0</pose>

			<inertial>
				<mass>0.00005</mass>
				<inertia>
					<ixx>0.00000001</ixx>
					<iyy>0.00000001</iyy>
					<izz>0.00000001</izz>
					<ixy>0</ixy>
					<ixz>0</ixz>
					<iyz>0</iyz>
				</inertia>
			</inertial>
			<!--
			<visual name="visual">
				<geometry>
					<box>
						<size>0.001 0.001 0.001</size>
					</box>
				</geometry>
			</visual>
			-->
			<sensor name="camera_1" type="camera">
				<pose>0.1150 -0.0606 0.001 0 1.571 0</pose>
				<camera>
					<horizontal_fov>1.8</horizontal_fov>
					<image>
						<width>10</width>
						<height>10</height>
					</image>
					<clip>
						<near>0.0001</near>
						<far>1</far>
					</clip>
				</camera>
				<always_on>1</always_on>
				<update_rate>1000</update_rate>
				<visualize>false</visualize>
			</sensor>
			<sensor name="camera_2" type="camera">
				<pose>0.1236 -0.0547 0.001 0 1.571 0</pose>
				<camera>
					<horizontal_fov>1.8</horizontal_fov>
					<image>
						<width>10</width>
						<height>10</height>
					</image>
					<clip>
						<near>0.0001</near>
						<far>1</far>
					</clip>
				</camera>
				<always_on>1</always_on>
				<update_rate>1000</update_rate>
				<visualize>false</visualize>
			</sensor>
			<sensor name="camera_3" type="camera">
				<pose>0.1313 -0.0476 0.001 0 1.571 0</pose>
				<camera>
					<horizontal_fov>1.8</horizontal_fov>
					<image>
						<width>10</width>
						<height>10</height>
					</image>
					<clip>
						<near>0.0001</near>
						<far>1</far>
					</clip>
				</camera>
				<always_on>1</always_on>
				<update_rate>1000</update_rate>
				<visualize>false</visualize>
			</sensor>
			<sensor name="camera_4" type="camera">
				<pose>0.1378 -0.0394 0.001 0 1.571 0</pose>
				<camera>
					<horizontal_fov>1.8</horizontal_fov>
					<image>
						<width>10</width>
						<height>10</height>
					</image>
					<clip>
						<near>0.0001</near>
						<far>1</far>
					</clip>
				</camera>
				<always_on>1</always_on>
				<update_rate>1000</update_rate>
				<visualize>false</visualize>
			</sensor>
			<sensor name="camera_5" type="camera">
				<pose>0.1431 -0.0304 0.001 0 1.571 0</pose>
				<camera>
					<horizontal_fov>1.8</horizontal_fov>
					<image>
						<width>10</width>
						<height>10</height>
					</image>
					<clip>
						<near>0.0001</near>
						<far>1</far>
					</clip>
				</camera>
				<always_on>1</always_on>
				<update_rate>1000</update_rate>
				<visualize>false</visualize>
			</sensor>
			<sensor name="camera_6" type="camera">
				<pose>0.1469 -0.0206 0.001 0 1.571 0</pose>
				<camera>
					<horizontal_fov>1.8</horizontal_fov>
					<image>
						<width>10</width>
						<height>10</height>
					</image>
					<clip>
						<near>0.0001</near>
						<far>1</far>
					</clip>
				</camera>
				<always_on>1</always_on>
				<update_rate>1000</update_rate>
				<visualize>false</visualize>
			</sensor>
			<sensor name="camera_7" type="camera">
				<pose>0.1492 -0.0104 0.001 0 1.571 0</pose>
				<camera>
					<horizontal_fov>1.8</horizontal_fov>
					<image>
						<width>10</width>
						<height>10</height>
					</image>
					<clip>
						<near>0.0001</near>
						<far>1</far>
					</clip>
				</camera>
				<always_on>1</always_on>
				<update_rate>1000</update_rate>
				<visualize>false</visualize>
			</sensor>
			<sensor name="camera_8" type="camera">
				<pose>0.15 0.0 0.001 0 1.571 0</pose>
				<camera>
					<horizontal_fov>1.8</horizontal_fov>
					<image>
						<width>10</width>
						<height>10</height>
					</image>
					<clip>
						<near>0.0001</near>
						<far>1</far>
					</clip>
				</camera>
				<always_on>1</always_on>
				<update_rate>1000</update_rate>
				<visualize>false</visualize>
			</sensor>
			<sensor name="camera_9" type="camera">
				<pose>0.1492 0.0104 0.001 0 1.571 0</pose>
				<camera>
					<horizontal_fov>1.8</horizontal_fov>
					<image>
						<width>10</width>
						<height>10</height>
					</image>
					<clip>
						<near>0.0001</near>
						<far>1</far>
					</clip>
				</camera>
				<always_on>1</always_on>
				<update_rate>1000</update_rate>
				<visualize>false</visualize>
			</sensor>
			<sensor name="camera_10" type="camera">
				<pose>0.1469 0.0206 0.001 0 1.571 0</pose>
				<camera>
					<horizontal_fov>1.8</horizontal_fov>
					<image>
						<width>10</width>
						<height>10</height>
					</image>
					<clip>
						<near>0.0001</near>
						<far>1</far>
					</clip>
				</camera>
				<always_on>1</always_on>
				<update_rate>1000</update_rate>
				<visualize>false</visualize>
			</sensor>
			<sensor name="camera_11" type="camera">
				<pose>0.1431 0.0304 0.001 0 1.571 0</pose>
				<camera>
					<horizontal_fov>1.8</horizontal_fov>
					<image>
						<width>10</width>
						<height>10</height>
					</image>
					<clip>
						<near>0.0001</near>
						<far>1</far>
					</clip>
				</camera>
				<always_on>1</always_on>
				<update_rate>1000</update_rate>
				<visualize>false</visualize>
			</sensor>
			<sensor name="camera_12" type="camera">
				<pose>0.1378 0.0394 0.001 0 1.571 0</pose>
				<camera>
					<horizontal_fov>1.8</horizontal_fov>
					<image>
						<width>10</width>
						<height>10</height>
					</image>
					<clip>
						<near>0.0001</near>
						<far>1</far>
					</clip>
				</camera>
				<always_on>1</always_on>
				<update_rate>1000</update_rate>
				<visualize>false</visualize>
			</sensor>
			<sensor name="camera_13" type="camera">
				<pose>0.1313 0.0476 0.001 0 1.571 0</pose>
				<camera>
					<horizontal_fov>1.8</horizontal_fov>
					<image>
						<width>10</width>
						<height>10</height>
					</image>
					<clip>
						<near>0.0001</near>
						<far>1</far>
					</clip>
				</camera>
				<always_on>1</always_on>
				<update_rate>1000</update_rate>
				<visualize>false</visualize>
			</sensor>
			<sensor name="camera_14" type="camera">
				<pose>0.1236 0.0547 0.001 0 1.571 0</pose>
				<camera>
					<horizontal_fov>1.8</horizontal_fov>
					<image>
						<width>10</width>
						<height>10</height>
					</image>
					<clip>
						<near>0.0001</near>
						<far>1</far>
					</clip>
				</camera>
				<always_on>1</always_on>
				<update_rate>1000</update_rate>
				<visualize>false</visualize>
			</sensor>
			<sensor name="camera_15" type="camera">
				<pose>0.1150 0.0606 0.001 0 1.571 0</pose>
				<camera>
					<horizontal_fov>1.8</horizontal_fov>
					<image>
						<width>10</width>
						<height>10</height>
					</image>
					<clip>
						<near>0.0001</near>
						<far>1</far>
					</clip>
				</camera>
				<always_on>1</always_on>
				<update_rate>1000</update_rate>
				<visualize>false</visualize>
			</sensor>
		</link>
<!-- ****************** Joint ****************** -->
		<joint type="revolute" name="right_front">
			<pose>0 0 0 0 0 0</pose>
			<child>right_front_wheel</child>
			<parent>chassis</parent>
			<axis>
				<xyz>0 1 0</xyz>
				<use_parent_model_frame>true</use_parent_model_frame>
				<limit>
					<velocity> 90 </velocity>
					<effort> 0.005 </effort>
				</limit>

				<dynamics> 
					<damping> 0.00001 </damping>
				</dynamics>
			</axis>
		</joint>
		<joint type="revolute" name="right_rear">
			<pose>0 0 0 0 0 0</pose>
			<child>right_rear_wheel</child>
			<parent>chassis</parent>
			<axis>
				<xyz>0 1 0</xyz>
				<use_parent_model_frame>true</use_parent_model_frame>
				<limit>
					<velocity> 90 </velocity>
					<effort> 0.005 </effort>
				</limit>
				<dynamics> 
					<damping> 0.00001 </damping>
				</dynamics>
			</axis>
		</joint>
		<joint type="revolute" name="left_front">
			<pose>0 0 0 0 0 0</pose>
			<child>left_front_wheel</child>
			<parent>chassis</parent>
			<axis>
				<xyz>0 1 0</xyz>
				<use_parent_model_frame>true</use_parent_model_frame>
				<limit>
					<velocity> 90 </velocity>
					<effort> 0.005 </effort>
				</limit>
				<dynamics> 
					<damping> 0.00001 </damping>
				</dynamics>
			</axis>
		</joint>
		<joint type="revolute" name="left_rear">
			<pose>0 0 0 0 0 0</pose>
			<child>left_rear_wheel</child>
			<parent>chassis</parent>
			<axis>
				<xyz>0 1 0</xyz>
				<use_parent_model_frame>true</use_parent_model_frame>
				<limit>
					<velocity> 90 </velocity>
					<effort> 0.005 </effort>
				</limit>
				<dynamics> 
					<damping> 0.00001 </damping>
				</dynamics>
			</axis>
		</joint>

		<joint type="fixed" name="camera_joint">
			<!--<pose>0.15 0.0 0.05 0 1.571 0</pose>-->
			<pose>0.0 0.0 0.0 0 0 0</pose>
			<child>camera_link</child>
			<parent>chassis</parent>
		</joint>
<!-- ****************** plugin****************** -->
<!--
		<plugin name="SkidSteerDrivePlugin" filename="libSkidSteerDrivePlugin.so">
			<right_front>right_front</right_front>
			<right_rear>right_rear</right_rear>
			<left_front>left_front</left_front>
			<left_rear>left_rear</left_rear>
			<MaxForce>0.1</MaxForce>
		</plugin>
-->
  </model>
</sdf>
