<?xml version="1.0"?>
<!--
	 SPDX-License-Identifier: GPL-3.0-only

	 Copyright (C) 2021  Haruki Shimotori. All right reserved.
-->


<sdf version="1.5">
	<model name="robotracer">
		<static>false</static>

<!-- ****************** Link ****************** -->
		<link name="chassis">
			<pose>0 0 0.0015 0 0 0</pose>
			<inertial>
				<mass>0.03</mass>
				<inertia>
					<ixx>0.0000252</ixx>
					<ixy>0.0</ixy>
					<ixz>0.0</ixz>
					<iyy>0.0000252</iyy>
					<iyz>0.0</iyz>
					<izz>0.00005</izz>
				</inertia>
			</inertial>

			<collision name="collision_base">
				<geometry>
					<box>
						<size>0.1 0.08 0.001</size>
					</box>
				</geometry>
			</collision>
			<visual name="visual_base">
				<geometry>
					<box>
						<size>0.1 0.08 0.001</size>
					</box>
				</geometry>
			</visual>
		</link>

		<link name="right_front_wheel">
			<pose>0.011 -0.055 0.009 1.5707 0 0</pose>

			<inertial>
				<mass>0.005</mass>
				<inertia>
					<ixx>0.0000003</ixx>
					<iyy>0.0000003</iyy>
					<izz>0.0000003</izz>
					<ixy>0</ixy>
					<ixz>0</ixz>
					<iyz>0</iyz>
				</inertia>
			</inertial>
			<collision name="collision">
				<geometry>
					<cylinder>
						<radius>0.01</radius>
						<length>0.01</length>
					</cylinder>
				</geometry>
				<surface>
					<friction>
						<ode>
							<mu>1</mu>
							<mu2>1</mu2>
							<slip1>0.5</slip1>
							<slip2>0</slip2>
						</ode>
					</friction>
				</surface>
			</collision>
			<visual name="visual">
				<geometry>
					<cylinder>
						<radius>0.01</radius>
						<length>0.01</length>
					</cylinder>
				</geometry>
			</visual>
		</link>

		<link name="left_front_wheel">
			<pose>0.011 0.055 0.009 1.5707 0 0</pose>

			<inertial>
				<mass>0.005</mass>
				<inertia>
					<ixx>0.0000003</ixx>
					<iyy>0.0000003</iyy>
					<izz>0.0000003</izz>
					<ixy>0</ixy>
					<ixz>0</ixz>
					<iyz>0</iyz>
				</inertia>
			</inertial>
			<collision name="collision">
				<geometry>
					<cylinder>
						<radius>0.01</radius>
						<length>0.01</length>
					</cylinder>
				</geometry>
				<surface>
					<friction>
						<ode>
							<mu>1</mu>
							<mu2>1</mu2>
							<slip1>0.5</slip1>
							<slip2>0</slip2>
						</ode>
					</friction>
				</surface>
			</collision>
			<visual name="visual">
				<geometry>
					<cylinder>
						<radius>0.01</radius>
						<length>0.01</length>
					</cylinder>
				</geometry>
			</visual>
		</link>

		<link name="right_rear_wheel">
			<pose>-0.011 -0.055 0.009 1.5707 0 0</pose>

			<inertial>
				<mass>0.005</mass>
				<inertia>
					<ixx>0.0000003</ixx>
					<iyy>0.0000003</iyy>
					<izz>0.0000003</izz>
					<ixy>0</ixy>
					<ixz>0</ixz>
					<iyz>0</iyz>
				</inertia>
			</inertial>
			<collision name="collision">
				<geometry>
					<cylinder>
						<radius>0.01</radius>
						<length>0.01</length>
					</cylinder>
				</geometry>
				<surface>
					<friction>
						<ode>
							<mu>1</mu>
							<mu2>1</mu2>
							<slip1>0.5</slip1>
							<slip2>0</slip2>
						</ode>
					</friction>
				</surface>
			</collision>
			<visual name="visual">
				<geometry>
					<cylinder>
						<radius>0.01</radius>
						<length>0.01</length>
					</cylinder>
				</geometry>
			</visual>
		</link>

		<link name="left_rear_wheel">
			<pose>-0.011 0.055 0.009 1.5707 0 0</pose>

			<inertial>
				<mass>0.005</mass>
				<inertia>
					<ixx>0.0000003</ixx>
					<iyy>0.0000003</iyy>
					<izz>0.0000003</izz>
					<ixy>0</ixy>
					<ixz>0</ixz>
					<iyz>0</iyz>
				</inertia>
			</inertial>
			<collision name="collision">
				<geometry>
					<cylinder>
						<radius>0.01</radius>
						<length>0.01</length>
					</cylinder>
				</geometry>
				<surface>
					<friction>
						<ode>
							<mu>1</mu>
							<mu2>1</mu2>
							<slip1>0.5</slip1>
							<slip2>0</slip2>
						</ode>
					</friction>
				</surface>
			</collision>
			<visual name="visual">
				<geometry>
					<cylinder>
						<radius>0.01</radius>
						<length>0.01</length>
					</cylinder>
				</geometry>
			</visual>
		</link>

<!-- ****************** Joint ****************** -->
		<joint type="revolute" name="right_front">
			<pose>0 0 0 0 0 0</pose>
			<child>right_front_wheel</child>
			<parent>chassis</parent>
			<axis>
				<xyz>0 1 0</xyz>
				<use_parent_model_frame>true</use_parent_model_frame>
			</axis>
		</joint>
		<joint type="revolute" name="right_rear">
			<pose>0 0 0 0 0 0</pose>
			<child>right_rear_wheel</child>
			<parent>chassis</parent>
			<axis>
				<xyz>0 1 0</xyz>
				<use_parent_model_frame>true</use_parent_model_frame>
			</axis>
		</joint>
		<joint type="revolute" name="left_front">
			<pose>0 0 0 0 0 0</pose>
			<child>left_front_wheel</child>
			<parent>chassis</parent>
			<axis>
				<xyz>0 1 0</xyz>
				<use_parent_model_frame>true</use_parent_model_frame>
			</axis>
		</joint>
		<joint type="revolute" name="left_rear">
			<pose>0 0 0 0 0 0</pose>
			<child>left_rear_wheel</child>
			<parent>chassis</parent>
			<axis>
				<xyz>0 1 0</xyz>
				<use_parent_model_frame>true</use_parent_model_frame>
			</axis>
		</joint>
	</model>
</sdf>
